Workbook

Sheet CAPA
B3: BIOCHAR CARBON NOVA ESPERANÇA
B5: Modelo Financeiro de Projeto
B6: Pirólise de Biomassa Residual de Eucalipto — Créditos de Carbono Voluntários
B9: INFORMAÇÕES DO PROJETO
B10: Projeto | C10: BCNE — Biochar Carbon Nova Esperança
B11: Tecnologia | C11: Pirólise lenta — Beston BST-30
B12: Horizonte | C12: 20 anos (2026–2045) + Ano 0 investimento (2025)
B13: Biomassa | C13: Resíduos lenhosos de colheita florestal (E. grandis × urophylla)
B14: Produto | C14: Créditos de carbono (Puro.Earth / EBC) + biochar (opcional)
B15: Localização | C15: Horto florestal — Nova Esperança
B16: Moeda | C16: R$ (Reais brasileiros) | Preço carbono em USD
B17: Versão do modelo | C17: v7 — Metodologia mássica Pincelli | Abril 2026
B18: Preparado por | C18: Astra Carbon
B19: Metodologia biomassa | C19: Pincelli et al. (2017) Scientia Forestalis v.45 n.115 — abordagem mássica direta
B21: ESTRUTURA DO MODELO
B22: PREMISSAS | C22: Inputs editáveis (azul) — cadeia de biomassa mássica, preços, energia, OPEX, financeiros
B23: CÁLCULO | C23: Cadeia biomassa → biochar → créditos certificáveis (20 anos)
B24: CAPEX | C24: Investimento inicial com breakdown e depreciação
B25: OPEX | C25: Custos operacionais variáveis e fixos projetados (20 anos)
B26: RECEITA | C26: Receita bruta/líquida: créditos de carbono + biochar opcional
B27: DRE_FCL | C27: Demonstrativo de resultado + Fluxo de caixa livre
B28: INDICADORES | C28: VPL, TIR, Payback, métricas operacionais ano-base
B29: SENSIBILIDADE | C29: Tabelas bidimensionais: TIR × preço × volume × CAPEX
B30: CENÁRIOS | C30: 4 cenários editáveis: Conservador, Base, Otimista, Premium
B31: ENERGIA | C31: Detalhamento de consumo e custo energético CEMIG A4 Azul
B32: DASHBOARD | C32: Gráficos dinâmicos: composição CAPEX, OPEX, EBITDA, FCL
B35: CONVENÇÕES DE FORMATAÇÃO
B36: Texto azul | C36: Input editável (hardcoded) — altere para cenários
B37: Texto preto | C37: Fórmula ou cálculo — NÃO editar
B38: Texto verde | C38: Link entre abas (cross-sheet reference)
B39: Fundo azul claro | C39: Célula de input
B40: Fundo amarelo claro | C40: Célula calculada
B42: DISCLAIMER: Este modelo é ferramenta de análise e não constitui recomendação de investimento.

Sheet INDICADORES
B1: INDICADORES FINANCEIROS | VPL, TIR, Payback
B3: VPL | C3: =DRE_FCL!E18+NPV(PREMISSAS!$C$101,DRE_FCL!F18:Y18) -> -1040546.1 | D3: TIR | E3: =IFERROR(IRR(DRE_FCL!E18:Y18),"N/D") -> 0.06945947 | J3: Helper: Ano | K3: FCL Desc. Acum.
J4: =DRE_FCL!E3 -> 2026 | K4: =DRE_FCL!E18/((1+PREMISSAS!$C$101)^0) -> -5498000
B5: PAYBACK (anos) | C5: =IFERROR(MATCH(TRUE,INDEX(DRE_FCL!F19:Y19>=0,0),0),">Horizonte") -> 11 | D5: CAPEX TOTAL | E5: =CAPEX!$C$16 -> 5498000 | J5: =DRE_FCL!F3 -> 2027 | K5: =K4+DRE_FCL!F18/((1+PREMISSAS!$C$101)^1) -> -4953165.2
B6: Payback Descontado (anos) | C6: =IFERROR(_xlfn.AGGREGATE(15,6,J4:J24/(K4:K24>=0),1)-PREMISSAS!$C$103,">Horizonte") -> >Horizonte | J6: =DRE_FCL!G3 -> 2028 | K6: =K5+DRE_FCL!G18/((1+PREMISSAS!$C$101)^2) -> -4469915.3
B7: RECEITA BRUTA MÉDIA (anual) | C7: =IFERROR(AVERAGE(DRE_FCL!F5:Y5),0) -> 2897370.5 | D7: EBITDA MÉDIO (anual) | E7: =IFERROR(AVERAGE(DRE_FCL!F8:Y8),0) -> 1013660 | J7: =DRE_FCL!H3 -> 2029 | K7: =K6+DRE_FCL!H18/((1+PREMISSAS!$C$101)^3) -> -4041556
J8: =DRE_FCL!I3 -> 2030 | K8: =K7+DRE_FCL!I18/((1+PREMISSAS!$C$101)^4) -> -3662100.8
B9: MARGEM EBITDA MÉDIA | C9: =IFERROR(E7/C7,0) -> 0.34985515 | D9: FCL TOTAL 20 ANOS | E9: =SUM(DRE_FCL!E18:Y18) -> 4519256.3 | J9: =DRE_FCL!J3 -> 2031 | K9: =K8+DRE_FCL!J18/((1+PREMISSAS!$C$101)^5) -> -3326198.3
J10: =DRE_FCL!K3 -> 2032 | K10: =K9+DRE_FCL!K18/((1+PREMISSAS!$C$101)^6) -> -3029065.8
B11: RESUMO OPERACIONAL — ANO BASE | J11: =DRE_FCL!L3 -> 2033 | K11: =K10+DRE_FCL!L18/((1+PREMISSAS!$C$101)^7) -> -2766430.3
B12: Alimentação do reator | C12: =CÁLCULO!F4 -> 3940.8425 | D12: t/ano | J12: =DRE_FCL!M3 -> 2034 | K12: =K11+DRE_FCL!M18/((1+PREMISSAS!$C$101)^8) -> -2534475.2
B13: Produção de biochar | C13: =CÁLCULO!F5 -> 1182.2528 | D13: t/ano | J13: =DRE_FCL!N3 -> 2035 | K13: =K12+DRE_FCL!N18/((1+PREMISSAS!$C$101)^9) -> -2329792.9
B14: Créditos certificáveis | C14: =CÁLCULO!F8 -> 3215.7275 | D14: tCO₂e | J14: =DRE_FCL!O3 -> 2036 | K14: =K13+DRE_FCL!O18/((1+PREMISSAS!$C$101)^10) -> -2149341.5
B15: Dias de operação efetiva | C15: =CÁLCULO!F9 -> 164.20177 | D15: dias | J15: =DRE_FCL!P3 -> 2037 | K15: =K14+DRE_FCL!P18/((1+PREMISSAS!$C$101)^11) -> -1985294.8
B16: Meses de calendário | C16: =CÁLCULO!F10 -> 6.5680709 | D16: meses | J16: =DRE_FCL!Q3 -> 2038 | K16: =K15+DRE_FCL!Q18/((1+PREMISSAS!$C$101)^12) -> -1836161.5
B17: Receita bruta carbono | C17: =RECEITA!F3 -> 2897370.5 | D17: R$ | J17: =DRE_FCL!R3 -> 2039 | K17: =K16+DRE_FCL!R18/((1+PREMISSAS!$C$101)^13) -> -1700585.7
B18: OPEX total | C18: =OPEX!F22 -> 1734535.5 | D18: R$ | J18: =DRE_FCL!S3 -> 2040 | K18: =K17+DRE_FCL!S18/((1+PREMISSAS!$C$101)^14) -> -1577335
B19: EBITDA | C19: =DRE_FCL!F8 -> 1162835 | D19: R$ | J19: =DRE_FCL!T3 -> 2041 | K19: =K18+DRE_FCL!T18/((1+PREMISSAS!$C$101)^15) -> -1465289
B20: FCL | C20: =DRE_FCL!F18 -> 599318.31 | D20: R$ | J20: =DRE_FCL!U3 -> 2042 | K20: =K19+DRE_FCL!U18/((1+PREMISSAS!$C$101)^16) -> -1363428.9
B21: Consumo elétrico (kWh/t ativo) | C21: =PREMISSAS!$C$48 -> 207.375 | D21: kWh/t | J21: =DRE_FCL!V3 -> 2043 | K21: =K20+DRE_FCL!V18/((1+PREMISSAS!$C$101)^17) -> -1270828.8
B22: Modalidade eletrica | C22: =PREMISSAS!$C$47 -> Cemig A4 Verde 360 kW | D22: contrato base | J22: =DRE_FCL!W3 -> 2044 | K22: =K21+DRE_FCL!W18/((1+PREMISSAS!$C$101)^18) -> -1186646.9
J23: =DRE_FCL!X3 -> 2045 | K23: =K22+DRE_FCL!X18/((1+PREMISSAS!$C$101)^19) -> -1110117.9
J24: =DRE_FCL!Y3 -> 2046 | K24: =K23+DRE_FCL!Y18/((1+PREMISSAS!$C$101)^20) -> -1040546.1

Sheet GLOSSÁRIO
B2: GLOSSÁRIO DE APRESENTAÇÃO — Termos técnicos, acrônimos e jargões do modelo BCNE
B3: Use este guia para antecipar perguntas. ⚠️ = ponto crítico que provavelmente será questionado.
B5: Termo / Acrônimo | C5: Onde aparece | D5: O que significa em linguagem simples | E5: Atenção / Resposta sugerida
B6: 1. METODOLOGIA E BIOMASSA
B7: Pirólise lenta | C7: CAPA, PREMISSAS A | D7: Aquecimento da biomassa a 400–700 °C sem oxigênio, transformando madeira em biochar (carvão vegetal estável).
B8: Biochar | C8: Modelo todo | D8: Carvão vegetal sólido produzido pela pirólise; estoca carbono por séculos quando aplicado ao solo.
B9: Metodologia mássica / Pincelli et al. (2017) | C9: PREMISSAS A, CAPA | D9: Abordagem que calcula resíduo florestal por massa (toneladas) em vez de volume (m³). Pincelli é o artigo científico de referência (Scientia Forestalis). | E9: ⚠️ Pode ser questionado por que escolheu essa metodologia. Resposta: é a referência acadêmica brasileira para E. grandis × urophylla, dá rastreabilidade auditável.
B10: E. grandis × E. urophylla (clone I144) | C10: PREMISSAS C6, CAPA | D10: Híbrido de eucalipto mais plantado no Brasil para celulose e energia. I144 é um clone comercial específico.
B11: Densidade básica do fuste | C11: PREMISSAS C6 | D11: Massa seca de madeira por m³ de tronco. Converte volume colhido em toneladas.
B12: Cominuição | C12: PREMISSAS A, C | D12: Trituração / moagem da biomassa em partículas menores antes de entrar no reator. | E12: Termo técnico — pode preferir dizer 'trituração' na fala.
B13: Fração lenhosa | C13: PREMISSAS C8 | D13: Parte do resíduo de campo que é madeira aproveitável (vs. folhas/casca fina que se perdem).
B14: Fuste | C14: PREMISSAS C6 | D14: Tronco principal da árvore (sem galhos e copa).
B15: Rendimento da pirólise | C15: PREMISSAS C28 | D15: % da biomassa seca que vira biochar. No modelo: 30% (de cada 1 t de madeira saem 300 kg de biochar). | E15: ⚠️ Pergunta provável: 'por que 30%?'. Resposta: faixa típica do BST-30 com madeira é 25–35%, base conservadora.
B17: 2. CRÉDITOS DE CARBONO E CERTIFICAÇÃO
B18: tCO₂e (toneladas de CO₂ equivalente) | C18: PREMISSAS B, INDICADORES | D18: Unidade padrão de crédito de carbono. 1 crédito = 1 tonelada de CO₂ evitada/sequestrada.
B19: Fator de carbono (2,72 tCO₂e/t biochar) | C19: PREMISSAS C32 | D19: Quanto CO₂ cada tonelada de biochar representa. Vem do carbono fixo × 44/12 (razão entre massa molecular de CO₂ e C). | E19: ⚠️ Se questionado o '44/12': átomo de carbono pesa 12, molécula de CO₂ pesa 44. É conversião estequiométrica padrão.
B20: C-loss / Desconto de permanência | D20: Desconto aplicado para refletir que parte do carbono pode degradar ao longo do tempo. Modelo usa 10%. | E20: ⚠️ Padrão exigido pelas certificadoras EBC/Puro.Earth (faixa 8–15%).
B21: EBC (European Biochar Certificate) | C21: PREMISSAS, CAPA | D21: Certificado europeu de biochar; estabelece padrões de qualidade e contabilidade de carbono.
B22: Puro.Earth | C22: PREMISSAS, CAPA | D22: Plataforma/registro de créditos de carbono de remoção de longa duração (carbon removal).
B23: MRV (Monitoring, Reporting & Verification) | C23: PREMISSAS F, CAPEX | D23: Sistema de Monitoramento, Relato e Verificação exigido para emitir créditos de carbono credíveis. | E23: ⚠️ Acrônimo crítico — explicar na primeira menção.
B24: ACV (Análise de Ciclo de Vida) | C24: PREMISSAS F | D24: Estudo que mede o impacto ambiental do projeto do berço ao tumulo (insumos, processo, transporte, uso final).
B25: LCA (Life Cycle Assessment) | C25: PREMISSAS D | D25: Mesmo que ACV — a sigla em inglês. 'Renovação LCA' = atualização anual da ACV exigida pela certificação. | E25: ⚠️ Aparece em inglês e português no mesmo modelo. Padronizar discurso.
B26: Mercado voluntário | C26: PREMISSAS C34 | D26: Compradores que adquirem créditos por escolha (ESG, net zero), não por obrigação regulatória. | E26: ⚠️ Pergunta provável: 'e o preço de USD 170/t é real?'. Faixa de remoção de alta qualidade (biochar/DAC) negocia entre USD 100–250.
B28: 3. ENERGIA E TARIFAS CEMIG
B29: Cemig A4 Verde | C29: PREMISSAS C, E | D29: Modalidade tarifária da Cemig para clientes industriais conectados em média tensão (2,3 a 25 kV). 'Verde' = tarifa única de demanda (sem distinção ponta/fora ponta na demanda). | E29: ⚠️ Pergunta crítica. Diferença vs. A4 Azul: Azul tem demanda separada para ponta e fora ponta; Verde tem demanda única + consumo diferenciado.
B30: Demanda contratada (kW) | C30: PREMISSAS E | D30: Potência que a empresa contrata firme com a Cemig. Paga mês a mês mesmo sem consumir. | E30: ⚠️ Custo fixo anual de 12 meses, mesmo operando 6 meses. Justificativa: contrato e infraestrutura de rede.
B31: Demanda de ultrapassagem | C31: PREMISSAS E | D31: Multa de 2x a tarifa quando o consumo excede a demanda contratada (>5% acima).
B32: Horário de ponta / fora ponta | C32: PREMISSAS E | D32: Ponta = 17h-20h em dias úteis (energia mais cara). Fora ponta = restante (mais barata). Modelo programa trituração fora de ponta.
B33: Gross-up de impostos (1,3113x) | C33: PREMISSAS E | D33: Multiplicador que converte tarifa 'sem impostos' em tarifa final paga (com ICMS, PIS, COFINS embutidos). | E33: Termo de engenharia tarifária. Em português: 'fator de bruto-líquido' ou simplesmente 'multiplicador de impostos'.
B34: kWh/t (consumo específico) | C34: PREMISSAS C, INDICADORES | D34: Energia elétrica gasta para processar 1 tonelada de biomassa. Modelo: 207 kWh/t.
B35: Roll-up por equipamento | C35: PREMISSAS C44, C45 | D35: Soma das potências por equipamento (britador, secador, reator) em vez de usar o número único do fornecedor. | E35: Termo do mundo de modelagem; pode dizer 'consolidação por equipamento'.
B36: Resolução Homologatória ANEEL 3.459/2025 | C36: PREMISSAS E | D36: Norma da agência reguladora que define as tarifas Cemig vigentes usadas no modelo.
B37: BST-30 (Beston) | C37: PREMISSAS A, F, CAPA | D37: Modelo do reator de pirólise comprado da fabricante chinesa Beston. Capacidade 1–1,5 t/h.
B38: Diesel S10 | C38: PREMISSAS E | D38: Diesel com baixo teor de enxofre (10 ppm), padrão brasileiro. Usado no aquecimento de partida do reator.
B39: QGBT / MT / BT / AT | C39: PREMISSAS F (Instalação elétrica) | D39: QGBT = Quadro Geral de Baixa Tensão. MT = Média Tensão. BT = Baixa Tensão. AT = Alta Tensão. | E39: ⚠️ Vários acrônimos juntos numa nota de célula (PREMISSAS!E97). Se alguém perguntar pelo CAPEX elétrico zerado, ter explicação pronta.
B41: 4. TRIBUTÁRIO
B42: Lucro Real | C42: PREMISSAS G, I, TRIBUTAÇÃO | D42: Regime de tributação no qual IRPJ e CSLL incidem sobre o lucro contábil ajustado, não sobre receita. | E42: ⚠️ Pergunta provável: 'por que Lucro Real e não Presumido?'. Resposta: receita projetada permite, e Lucro Real aproveita prejuízo fiscal nos primeiros anos.
B43: PIS / COFINS | C43: PREMISSAS I, TRIBUTAÇÃO | D43: Contribuições federais sobre receita. Lucro Real → regime não cumulativo (1,65% + 7,6%). | E43: ⚠️ Créditos de carbono: ZERO de PIS/COFINS pela Lei 15.042/2024 art. 19 — vantagem fiscal importante para destacar.
B44: IRPJ / CSLL | C44: PREMISSAS I, TRIBUTAÇÃO | D44: IRPJ = Imposto de Renda Pessoa Jurídica (15% + 10% adicional). CSLL = Contribuição Social sobre Lucro Líquido (9%).
B45: Lei 15.042/2024 | C45: PREMISSAS I | D45: Lei brasileira que regulamentou o mercado de carbono e desonerou de PIS/COFINS a alienação de créditos. | E45: ⚠️ Pode ser perguntado se isso é firme. Sim, está em lei sancionada. Apenas regulamentações operacionais pendentes.
...

Sheet PREMISSAS
B1: PREMISSAS DO MODELO | Biochar Carbon Nova Esperança v7 — Metodologia Mássica
B2: Azul = input editável | Amarelo = calculado | Coluna E = fonte/referência auditável
B3: Premissa | C3: Valor | D3: Unidade | E3: Fonte / Referência
B4: A — CADEIA DE BIOMASSA (Abordagem Mássica — Pincelli et al., 2017)
B5: Volume de colheita anual | C5: 182690 | D5: m³/ano | E5: Área concessionada; referência campo 2024
B6: Densidade básica do fuste | C6: 0.48 | D6: t/m³ | E6: E. grandis × E. urophylla clone I144, 7 anos — lit. 0,44–0,50
B7: Fração mássica de resíduo de campo (%) | C7: 0.06 | D7: % | E7: Pincelli et al. (2017) Tab.1: 8,2 t/ha ÷ 136,4 t/ha = 6,0%. Resíduo total 60d pós-colheita.
B8: Fração lenhosa aproveitável (% resíduo) | C8: 0.749 | D8: % | E8: Pincelli et al. (2017) Tab.3: 74,9% madeira c/ casca no resíduo total
B9: Massa de produção (t/ano) | C9: =C5*C6 -> 87691.2 | D9: t/ano | E9: Calculado: volume colheita × densidade básica fuste
B10: Massa de resíduo bruto de campo (t/ano) | C10: =C9*C7 -> 5261.472 | D10: t/ano | E10: Calculado: massa produção × 6,0% (Pincelli 2017)
B11: Fração lenhosa seca disponível (t/ano) | C11: =C10*C8 -> 3940.8425 | D11: t/ano | E11: Calculado: resíduo bruto × 74,9% fração lenhosa
B12: Biomassa na porteira da planta (t/ano) | C12: =C11 -> 3940.8425 | D12: t/ano | E12: Após perda no transporte
B13: ALIMENTAÇÃO DO REATOR (t/ano) | C13: =C12 -> 3940.8425 | D13: t/ano | E13: Após cominuição — BASE de todo o modelo
B15: Ciclo Operacional do Reator (Beston BST-30)
B16: Dias de operação por ciclo | C16: 10 | D16: dias | E16: Beston: ciclo padrão operação contínua
B17: Dias de manutenção por ciclo | C17: 2 | D17: dias | E17: Limpeza + manutenção preventiva
B18: Disponibilidade efetiva do reator (%) | C18: =C16/(C16+C17) -> 0.83333333
B19: Capacidade do reator (t seca/h) | C19: 1 | D19: t/h | E19: Beston BST-30: 1,0–1,5 t/h; base conservadora
B20: Horas de operação por dia | C20: 24 | D20: h/dia | E20: Operação contínua — reator industrial
B21: Horas de operação efetiva/ano | C21: =C13/C19 -> 3940.8425 | D21: h/ano
B22: Dias de operação efetiva/ano | C22: =C21/C20 -> 164.20177 | D22: dias/ano | E22: Calculado: C15/C21/C22 (alimentação ÷ cap. reator ÷ h/dia). Alimenta: OPEX (mão de obra, manutenção), ENERGIA e indicadores operacionais.
B23: Dias de calendário necessários/ano | C23: =C22/C18 -> 197.04213 | D23: dias/ano
B24: Meses de calendário necessários/ano | C24: =C23/30 -> 6.5680709 | D24: meses/ano
B25: Número de ciclos de manutenção/ano | C25: =ROUNDUP(C22/C16,0) -> 17 | D25: ciclos | E25: Ciclos discretos: arredonda para cima para refletir startup/manutencao por ciclo inteiro.
B26: Rendimento da pirólise (%) | C26: 0.3 | D26: % | E26: Biochar/alimentação seca; BST-30+madeira: 25–35%. Base: 30%
B27: B — CRÉDITOS DE CARBONO E PREÇO
B28: Fator de carbono (tCO₂e / t biochar) | C28: 2.72 | D28: tCO₂e/t | E28: EBC/Puro.Earth — carbono fixo × 44/12
B30: Preço do crédito de carbono (USD/tCO₂e) | C30: 170 | D30: USD/tCO₂e | E30: Mercado voluntário — premissa base
B31: Taxa de câmbio USD/BRL | C31: 5.3 | D31: R$/USD | E31: Câmbio fixo — atualizar conforme cenário
B32: Preço de venda do biochar (R$/t) | C32: 0 | D32: R$/t | E32: Opcional — 0 = desligado
B33: Receita de biochar ativa? (1=Sim, 0=Não) | C33: 0 | D33: 1/0 | E33: Toggle: ativa/desativa linha de receita biochar
B35: C - ENERGIA ELETRICA | Contrato Cemig A4 Verde - Montes Claros/MG
B36: Operacao real contratada
B37: Capacidade cominuicao (t seca/h) | C37: 4 | D37: t/h | E37: Linha de cominuicao trabalha 6h/dia; capacidade nominal 3-5 t/h, base 4 t/h.
B38: Potencia media cominuicao | C38: 164.5 | D38: kW | E38: Roll-up fase 1: britagem/peneiramento + recirculacao media.
B39: Potencia media pirolise 24h | C39: 166.25 | D39: kW | E39: Roll-up fase 2: secador + reator + auxiliares.
B40: kWh/t cominuicao | C40: =C38/C37 -> 41.125 | D40: kWh/t
B41: kWh/t pirolise | C41: =C39/C19 -> 166.25 | D41: kWh/t
B42: Consumo especifico processo | C42: =C40+C41 -> 207.375 | D42: kWh/t | E42: Cominuicao 6h/dia + pirolise 24h/dia; secador tratado na pirolise.
B44: Consumo eletrico de startup por ciclo | C44: 120 | D44: kWh/ciclo | E44: Auxiliares eletricos de partida; aquecimento principal via diesel/gas.
...

Sheet CÁLCULO
B1: CÁLCULO | Cadeia Biomassa → Biochar → Créditos
B2: Metodologia mássica (Pincelli 2017). Ano 0 = investimento, Anos 1–20 = operação.
B3: Variável | C3: Unidade | D3: Referência | E3: 2026 | F3: 2027 | G3: 2028 | H3: 2029 | I3: 2030 | J3: 2031 | K3: 2032 | L3: 2033 | M3: 2034 | N3: 2035 | O3: 2036 | P3: 2037 | Q3: 2038 | R3: 2039 | S3: 2040 | T3: 2041 | U3: 2042 | V3: 2043 | W3: 2044 | X3: 2045 | Y3: 2046
B4: Alimentação do reator | C4: t/ano | D4: PREMISSAS — cadeia mássica | E4: 0 | F4: =PREMISSAS!$C$13 -> 3940.8425 | G4: =PREMISSAS!$C$13 -> 3940.8425 | H4: =PREMISSAS!$C$13 -> 3940.8425 | I4: =PREMISSAS!$C$13 -> 3940.8425 | J4: =PREMISSAS!$C$13 -> 3940.8425 | K4: =PREMISSAS!$C$13 -> 3940.8425 | L4: =PREMISSAS!$C$13 -> 3940.8425 | M4: =PREMISSAS!$C$13 -> 3940.8425 | ... Y4: =PREMISSAS!$C$13 -> 3940.8425
B5: Produção de biochar | C5: t/ano | D5: bio × rend | E5: 0 | F5: =F4*PREMISSAS!$C$26 -> 1182.2528 | G5: =G4*PREMISSAS!$C$26 -> 1182.2528 | H5: =H4*PREMISSAS!$C$26 -> 1182.2528 | I5: =I4*PREMISSAS!$C$26 -> 1182.2528 | J5: =J4*PREMISSAS!$C$26 -> 1182.2528 | K5: =K4*PREMISSAS!$C$26 -> 1182.2528 | L5: =L4*PREMISSAS!$C$26 -> 1182.2528 | M5: =M4*PREMISSAS!$C$26 -> 1182.2528 | ... Y5: =Y4*PREMISSAS!$C$26 -> 1182.2528
B6: Carbono fixado bruto | C6: tCO₂e | D6: biochar × fc | E6: 0 | F6: =F5*PREMISSAS!$C$28 -> 3215.7275 | G6: =G5*PREMISSAS!$C$28 -> 3215.7275 | H6: =H5*PREMISSAS!$C$28 -> 3215.7275 | I6: =I5*PREMISSAS!$C$28 -> 3215.7275 | J6: =J5*PREMISSAS!$C$28 -> 3215.7275 | K6: =K5*PREMISSAS!$C$28 -> 3215.7275 | L6: =L5*PREMISSAS!$C$28 -> 3215.7275 | M6: =M5*PREMISSAS!$C$28 -> 3215.7275 | ... Y6: =Y5*PREMISSAS!$C$28 -> 3215.7275
B8: CRÉDITOS LÍQUIDOS CERTIFICÁVEIS | C8: tCO₂e | D8: bruto − closs | E8: 0 | F8: =F6-F7 -> 3215.7275 | G8: =G6-G7 -> 3215.7275 | H8: =H6-H7 -> 3215.7275 | I8: =I6-I7 -> 3215.7275 | J8: =J6-J7 -> 3215.7275 | K8: =K6-K7 -> 3215.7275 | L8: =L6-L7 -> 3215.7275 | M8: =M6-M7 -> 3215.7275 | ... Y8: =Y6-Y7 -> 3215.7275
B9: Dias de operação efetiva | C9: dias/ano | D9: PREMISSAS | E9: 0 | F9: =PREMISSAS!$C$22 -> 164.20177 | G9: =PREMISSAS!$C$22 -> 164.20177 | H9: =PREMISSAS!$C$22 -> 164.20177 | I9: =PREMISSAS!$C$22 -> 164.20177 | J9: =PREMISSAS!$C$22 -> 164.20177 | K9: =PREMISSAS!$C$22 -> 164.20177 | L9: =PREMISSAS!$C$22 -> 164.20177 | M9: =PREMISSAS!$C$22 -> 164.20177 | ... Y9: =PREMISSAS!$C$22 -> 164.20177
B10: Meses de calendário | C10: meses/ano | D10: PREMISSAS | E10: 0 | F10: =PREMISSAS!$C$24 -> 6.5680709 | G10: =PREMISSAS!$C$24 -> 6.5680709 | H10: =PREMISSAS!$C$24 -> 6.5680709 | I10: =PREMISSAS!$C$24 -> 6.5680709 | J10: =PREMISSAS!$C$24 -> 6.5680709 | K10: =PREMISSAS!$C$24 -> 6.5680709 | L10: =PREMISSAS!$C$24 -> 6.5680709 | M10: =PREMISSAS!$C$24 -> 6.5680709 | ... Y10: =PREMISSAS!$C$24 -> 6.5680709

Sheet CAPEX
B1: CAPEX | Investimento Inicial e Depreciação
B2: Componente | C2: Valor (R$) | D2: % Total | E2: Fonte
B3: Instalação elétrica | C3: =PREMISSAS!C85 -> 0 | D3: =IF($C$16>0,C3/$C$16,0) -> 0 | E3: Grid + distribuição interna
B4: Terraplanagem e drenagem | C4: =PREMISSAS!C86 -> 300000 | D4: =IF($C$16>0,C4/$C$16,0) -> 0.054565296 | E4: Preparo do sítio
B5: Infraestrutura civil | C5: =PREMISSAS!C87 -> 400000 | D5: =IF($C$16>0,C5/$C$16,0) -> 0.072753729 | E5: Galpões, cercamento, acesso
B6: Reator de pirólise BST-30 | C6: =PREMISSAS!C88 -> 2210000 | D6: =IF($C$16>0,C6/$C$16,0) -> 0.40196435 | E6: Equipamento principal importado
B7: Linha de cominuição / triturador | C7: =PREMISSAS!C89 -> 240000 | D7: =IF($C$16>0,C7/$C$16,0) -> 0.043652237 | E7: Picador + moinho de martelos
B8: Secador de biomassa | C8: =PREMISSAS!C90 -> 150000 | D8: =IF($C$16>0,C8/$C$16,0) -> 0.027282648 | E8: Pré-tratamento de umidade
B9: Frete + seguro + sobressalentes | C9: =PREMISSAS!C91 -> 312000 | D9: =IF($C$16>0,C9/$C$16,0) -> 0.056747908 | E9: Importação + logística
B10: Montagem e comissionamento | C10: =PREMISSAS!C92 -> 450000 | D10: =IF($C$16>0,C10/$C$16,0) -> 0.081847945 | E10: Engenheiro Beston + equipe local
B11: Pequena Subestacao de energia | C11: =PREMISSAS!C93 -> 400000 | D11: =IF($C$16>0,C11/$C$16,0) -> 0.072753729 | E11: Transformador, QG, protecao e cabeamento MT/BT
B12: Análise de Ciclo de Vida (ACV) | C12: =PREMISSAS!C94 -> 45000 | D12: =IF($C$16>0,C12/$C$16,0) -> 0.0081847945 | E12: Parceria Gron — ACV inicial
B13: Plano de MRV e data room | C13: =PREMISSAS!C95 -> 150000 | D13: =IF($C$16>0,C13/$C$16,0) -> 0.027282648 | E13: Framework + estrutura documental
B14: Auditoria e certificação inicial | C14: =PREMISSAS!C96 -> 100000 | D14: =IF($C$16>0,C14/$C$16,0) -> 0.018188432 | E14: Validação de 3ª parte
B15: Serviços Astra Carbon | C15: =PREMISSAS!C97 -> 741000 | D15: =IF($C$16>0,C15/$C$16,0) -> 0.13477628 | E15: Originação+ Desenvolvimento + Certficação
B16: CAPEX TOTAL | C16: =SUM(C3:C15) -> 5498000
B18: DEPRECIAÇÃO | E18: NOTA: Linha C22 é valor de referência. Depreciação real por ano em E22:Y22 (zera após vida útil).
B19: CAPEX Físico | C19: =C3+C4+C5+C6+C7+C8+C9+C10+C11 -> 4462000 | D19: =IF($C$16>0,C19/$C$16,0) -> 0.81156784
E21: 2026 | F21: 2027 | G21: 2028 | H21: 2029 | I21: 2030 | J21: 2031 | K21: 2032 | L21: 2033 | M21: 2034 | N21: 2035 | O21: 2036 | P21: 2037 | Q21: 2038 | R21: 2039 | S21: 2040 | T21: 2041 | U21: 2042 | V21: 2043 | W21: 2044 | X21: 2045 | Y21: 2046
B22: Depreciação anual — Ano 1 ref. | C22: =IF(PREMISSAS!C100>0,C19/PREMISSAS!C100,0) -> 223100 | E22: =IF(AND(2026>=PREMISSAS!$C$104,2026<PREMISSAS!$C$104+PREMISSAS!$C$100),IF(PREMISSAS!$C$100>0,$C$19/PREMISSAS!$C$100,0),0) -> 0 | F22: =IF(AND(2027>=PREMISSAS!$C$104,2027<PREMISSAS!$C$104+PREMISSAS!$C$100),IF(PREMISSAS!$C$100>0,$C$19/PREMISSAS!$C$100,0),0) -> 223100 | G22: =IF(AND(2028>=PREMISSAS!$C$104,2028<PREMISSAS!$C$104+PREMISSAS!$C$100),IF(PREMISSAS!$C$100>0,$C$19/PREMISSAS!$C$100,0),0) -> 223100 | H22: =IF(AND(2029>=PREMISSAS!$C$104,2029<PREMISSAS!$C$104+PREMISSAS!$C$100),IF(PREMISSAS!$C$100>0,$C$19/PREMISSAS!$C$100,0),0) -> 223100 | I22: =IF(AND(2030>=PREMISSAS!$C$104,2030<PREMISSAS!$C$104+PREMISSAS!$C$100),IF(PREMISSAS!$C$100>0,$C$19/PREMISSAS!$C$100,0),0) -> 223100 | J22: =IF(AND(2031>=PREMISSAS!$C$104,2031<PREMISSAS!$C$104+PREMISSAS!$C$100),IF(PREMISSAS!$C$100>0,$C$19/PREMISSAS!$C$100,0),0) -> 223100 | K22: =IF(AND(2032>=PREMISSAS!$C$104,2032<PREMISSAS!$C$104+PREMISSAS!$C$100),IF(PREMISSAS!$C$100>0,$C$19/PREMISSAS!$C$100,0),0) -> 223100 | L22: =IF(AND(2033>=PREMISSAS!$C$104,2033<PREMISSAS!$C$104+PREMISSAS!$C$100),IF(PREMISSAS!$C$100>0,$C$19/PREMISSAS!$C$100,0),0) -> 223100 | M22: =IF(AND(2034>=PREMISSAS!$C$104,2034<PREMISSAS!$C$104+PREMISSAS!$C$100),IF(PREMISSAS!$C$100>0,$C$19/PREMISSAS!$C$100,0),0) -> 223100 | N22: =IF(AND(2035>=PREMISSAS!$C$104,2035<PREMISSAS!$C$104+PREMISSAS!$C$100),IF(PREMISSAS!$C$100>0,$C$19/PREMISSAS!$C$100,0),0) -> 223100 | O22: =IF(AND(2036>=PREMISSAS!$C$104,2036<PREMISSAS!$C$104+PREMISSAS!$C$100),IF(PREMISSAS!$C$100>0,$C$19/PREMISSAS!$C$100,0),0) -> 223100 | P22: =IF(AND(2037>=PREMISSAS!$C$104,2037<PREMISSAS!$C$104+PREMISSAS!$C$100),IF(PREMISSAS!$C$100>0,$C$19/PREMISSAS!$C$100,0),0) -> 223100 | Q22: =IF(AND(2038>=PREMISSAS!$C$104,2038<PREMISSAS!$C$104+PREMISSAS!$C$100),IF(PREMISSAS!$C$100>0,$C$19/PREMISSAS!$C$100,0),0) -> 223100 | R22: =IF(AND(2039>=PREMISSAS!$C$104,2039<PREMISSAS!$C$104+PREMISSAS!$C$100),IF(PREMISSAS!$C$100>0,$C$19/PREMISSAS!$C$100,0),0) -> 223100 | S22: =IF(AND(2040>=PREMISSAS!$C$104,2040<PREMISSAS!$C$104+PREMISSAS!$C$100),IF(PREMISSAS!$C$100>0,$C$19/PREMISSAS!$C$100,0),0) -> 223100 | T22: =IF(AND(2041>=PREMISSAS!$C$104,2041<PREMISSAS!$C$104+PREMISSAS!$C$100),IF(PREMISSAS!$C$100>0,$C$19/PREMISSAS!$C$100,0),0) -> 223100 | U22: =IF(AND(2042>=PREMISSAS!$C$104,2042<PREMISSAS!$C$104+PREMISSAS!$C$100),IF(PREMISSAS!$C$100>0,$C$19/PREMISSAS!$C$100,0),0) -> 223100 | V22: =IF(AND(2043>=PREMISSAS!$C$104,2043<PREMISSAS!$C$104+PREMISSAS!$C$100),IF(PREMISSAS!$C$100>0,$C$19/PREMISSAS!$C$100,0),0) -> 223100 | W22: =IF(AND(2044>=PREMISSAS!$C$104,2044<PREMISSAS!$C$104+PREMISSAS!$C$100),IF(PREMISSAS!$C$100>0,$C$19/PREMISSAS!$C$100,0),0) -> 223100 | X22: =IF(AND(2045>=PREMISSAS!$C$104,2045<PREMISSAS!$C$104+PREMISSAS!$C$100),IF(PREMISSAS!$C$100>0,$C$19/PREMISSAS!$C$100,0),0) -> 223100 | Y22: =IF(AND(2046>=PREMISSAS!$C$104,2046<PREMISSAS!$C$104+PREMISSAS!$C$100),IF(PREMISSAS!$C$100>0,$C$19/PREMISSAS!$C$100,0),0) -> 223100
B24: Depreciação anual (D&A) — lida pela DRE_FCL | C24: =C22 -> 223100 | E24: =E22 -> 0 | F24: =F22 -> 223100 | G24: =G22 -> 223100 | H24: =H22 -> 223100 | I24: =I22 -> 223100 | J24: =J22 -> 223100 | K24: =K22 -> 223100 | L24: =L22 -> 223100 | ... Y24: =Y22 -> 223100
B26: Vida útil | C26: =PREMISSAS!C100 -> 20 | D26: anos

Sheet RECEITA
B1: RECEITA | Créditos de Carbono + Venda Opcional de Biochar
B2: Linha de Receita | C2: Fórmula | D2: Referência | E2: 2026 | F2: 2027 | G2: 2028 | H2: 2029 | I2: 2030 | J2: 2031 | K2: 2032 | L2: 2033 | M2: 2034 | N2: 2035 | O2: 2036 | P2: 2037 | Q2: 2038 | R2: 2039 | S2: 2040 | T2: 2041 | U2: 2042 | V2: 2043 | W2: 2044 | X2: 2045 | Y2: 2046
B3: Receita créditos carbono (tCO₂e × USD × fx) | C3: créditos×USD×fx | D3: cred×preço×fx | E3: 0 | F3: =CÁLCULO!F8*PREMISSAS!$C$30*PREMISSAS!$C$31 -> 2897370.5 | G3: =CÁLCULO!G8*PREMISSAS!$C$30*PREMISSAS!$C$31 -> 2897370.5 | H3: =CÁLCULO!H8*PREMISSAS!$C$30*PREMISSAS!$C$31 -> 2897370.5 | I3: =CÁLCULO!I8*PREMISSAS!$C$30*PREMISSAS!$C$31 -> 2897370.5 | J3: =CÁLCULO!J8*PREMISSAS!$C$30*PREMISSAS!$C$31 -> 2897370.5 | K3: =CÁLCULO!K8*PREMISSAS!$C$30*PREMISSAS!$C$31 -> 2897370.5 | L3: =CÁLCULO!L8*PREMISSAS!$C$30*PREMISSAS!$C$31 -> 2897370.5 | M3: =CÁLCULO!M8*PREMISSAS!$C$30*PREMISSAS!$C$31 -> 2897370.5 | ... Y3: =CÁLCULO!Y8*PREMISSAS!$C$30*PREMISSAS!$C$31 -> 2897370.5
B4: Receita biochar (toggle × t × R$/t) | C4: toggle×t×R$/t | D4: toggle×bchar×preço | E4: 0 | F4: =PREMISSAS!$C$33*CÁLCULO!F5*PREMISSAS!$C$32 -> 0 | G4: =PREMISSAS!$C$33*CÁLCULO!G5*PREMISSAS!$C$32 -> 0 | H4: =PREMISSAS!$C$33*CÁLCULO!H5*PREMISSAS!$C$32 -> 0 | I4: =PREMISSAS!$C$33*CÁLCULO!I5*PREMISSAS!$C$32 -> 0 | J4: =PREMISSAS!$C$33*CÁLCULO!J5*PREMISSAS!$C$32 -> 0 | K4: =PREMISSAS!$C$33*CÁLCULO!K5*PREMISSAS!$C$32 -> 0 | L4: =PREMISSAS!$C$33*CÁLCULO!L5*PREMISSAS!$C$32 -> 0 | M4: =PREMISSAS!$C$33*CÁLCULO!M5*PREMISSAS!$C$32 -> 0 | ... Y4: =PREMISSAS!$C$33*CÁLCULO!Y5*PREMISSAS!$C$32 -> 0
B5: RECEITA BRUTA TOTAL | D5: carb+bchar | E5: 0 | F5: =F3+F4 -> 2897370.5 | G5: =G3+G4 -> 2897370.5 | H5: =H3+H4 -> 2897370.5 | I5: =I3+I4 -> 2897370.5 | J5: =J3+J4 -> 2897370.5 | K5: =K3+K4 -> 2897370.5 | L5: =L3+L4 -> 2897370.5 | M5: =M3+M4 -> 2897370.5 | ... Y5: =Y3+Y4 -> 2897370.5
B6: (–) Fee Astra Carbon (% receita bruta) | C6: % × bruta | D6: astra×bruta | E6: 0 | F6: =-F5*PREMISSAS!$C$102 -> 0 | G6: =-G5*PREMISSAS!$C$102 -> 0 | H6: =-H5*PREMISSAS!$C$102 -> 0 | I6: =-I5*PREMISSAS!$C$102 -> 0 | J6: =-J5*PREMISSAS!$C$102 -> 0 | K6: =-K5*PREMISSAS!$C$102 -> 0 | L6: =-L5*PREMISSAS!$C$102 -> 0 | M6: =-M5*PREMISSAS!$C$102 -> 0 | ... Y6: =-Y5*PREMISSAS!$C$102 -> 0
B7: (removida — receita líquida calculada no DRE_FCL) | D7: bruta+astra

Sheet TRIBUTAÇÃO
B1: TRIBUTOS - LUCRO REAL
A2: PIS/COFINS sobre créditos de carbono: 9,25% (1,65% PIS + 7,6% COFINS) — sem isenção | B2: Creditos de carbono: sem incidencia de PIS/COFINS na alienacao (Lei 15.042/2024, art. 19). IRPJ/CSLL sobre lucro real anual com compensacao de prejuizo fiscal e base negativa de CSLL.
B3: Item | C3: Origem | D3: Referencia | E3: 2026 | F3: 2027 | G3: 2028 | H3: 2029 | I3: 2030 | J3: 2031 | K3: 2032 | L3: 2033 | M3: 2034 | N3: 2035 | O3: 2036 | P3: 2037 | Q3: 2038 | R3: 2039 | S3: 2040 | T3: 2041 | U3: 2042 | V3: 2043 | W3: 2044 | X3: 2045 | Y3: 2046
B4: Receita creditos carbono | C4: RECEITA | D4: -> RECEITA!3 | E4: =RECEITA!E3 -> 0 | F4: =RECEITA!F3 -> 2897370.5 | G4: =RECEITA!G3 -> 2897370.5 | H4: =RECEITA!H3 -> 2897370.5 | I4: =RECEITA!I3 -> 2897370.5 | J4: =RECEITA!J3 -> 2897370.5 | K4: =RECEITA!K3 -> 2897370.5 | L4: =RECEITA!L3 -> 2897370.5 | ... Y4: =RECEITA!Y3 -> 2897370.5
B5: Receita biochar | C5: RECEITA | D5: -> RECEITA!4 | E5: =RECEITA!E4 -> 0 | F5: =RECEITA!F4 -> 0 | G5: =RECEITA!G4 -> 0 | H5: =RECEITA!H4 -> 0 | I5: =RECEITA!I4 -> 0 | J5: =RECEITA!J4 -> 0 | K5: =RECEITA!K4 -> 0 | L5: =RECEITA!L4 -> 0 | ... Y5: =RECEITA!Y4 -> 0
B6: Receita bruta total | C6: Calculado | D6: 4+5 | E6: =E4+E5 -> 0 | F6: =F4+F5 -> 2897370.5 | G6: =G4+G5 -> 2897370.5 | H6: =H4+H5 -> 2897370.5 | I6: =I4+I5 -> 2897370.5 | J6: =J4+J5 -> 2897370.5 | K6: =K4+K5 -> 2897370.5 | L6: =L4+L5 -> 2897370.5 | ... Y6: =Y4+Y5 -> 2897370.5
B7: PIS bruto - biochar | C7: PREMISSAS | D7: biochar x aliquota | E7: =E5*PREMISSAS!$C$111 -> 0 | F7: =F5*PREMISSAS!$C$111 -> 0 | G7: =G5*PREMISSAS!$C$111 -> 0 | H7: =H5*PREMISSAS!$C$111 -> 0 | I7: =I5*PREMISSAS!$C$111 -> 0 | J7: =J5*PREMISSAS!$C$111 -> 0 | K7: =K5*PREMISSAS!$C$111 -> 0 | L7: =L5*PREMISSAS!$C$111 -> 0 | ... Y7: =Y5*PREMISSAS!$C$111 -> 0
B8: COFINS bruto - biochar | C8: PREMISSAS | D8: biochar x aliquota | E8: =E5*PREMISSAS!$C$112 -> 0 | F8: =F5*PREMISSAS!$C$112 -> 0 | G8: =G5*PREMISSAS!$C$112 -> 0 | H8: =H5*PREMISSAS!$C$112 -> 0 | I8: =I5*PREMISSAS!$C$112 -> 0 | J8: =J5*PREMISSAS!$C$112 -> 0 | K8: =K5*PREMISSAS!$C$112 -> 0 | L8: =L5*PREMISSAS!$C$112 -> 0 | ... Y8: =Y5*PREMISSAS!$C$112 -> 0
B9: Base estimada de credito PIS/COFINS | C9: PREMISSAS | D9: OPEX caixa x fracao elegivel | E9: 0 | F9: =IF(OPEX!F22>0,OPEX!F22*PREMISSAS!$C$113,0) -> 0 | G9: =IF(OPEX!G22>0,OPEX!G22*PREMISSAS!$C$113,0) -> 0 | H9: =IF(OPEX!H22>0,OPEX!H22*PREMISSAS!$C$113,0) -> 0 | I9: =IF(OPEX!I22>0,OPEX!I22*PREMISSAS!$C$113,0) -> 0 | J9: =IF(OPEX!J22>0,OPEX!J22*PREMISSAS!$C$113,0) -> 0 | K9: =IF(OPEX!K22>0,OPEX!K22*PREMISSAS!$C$113,0) -> 0 | L9: =IF(OPEX!L22>0,OPEX!L22*PREMISSAS!$C$113,0) -> 0 | M9: =IF(OPEX!M22>0,OPEX!M22*PREMISSAS!$C$113,0) -> 0 | ... Y9: =IF(OPEX!Y22>0,OPEX!Y22*PREMISSAS!$C$113,0) -> 0
B10: Credito PIS estimado | C10: Calculado | D10: 9 x aliquota PIS | E10: =E9*PREMISSAS!$C$111 -> 0 | F10: =F9*PREMISSAS!$C$111 -> 0 | G10: =G9*PREMISSAS!$C$111 -> 0 | H10: =H9*PREMISSAS!$C$111 -> 0 | I10: =I9*PREMISSAS!$C$111 -> 0 | J10: =J9*PREMISSAS!$C$111 -> 0 | K10: =K9*PREMISSAS!$C$111 -> 0 | L10: =L9*PREMISSAS!$C$111 -> 0 | ... Y10: =Y9*PREMISSAS!$C$111 -> 0
B11: Credito COFINS estimado | C11: Calculado | D11: 9 x aliquota COFINS | E11: =E9*PREMISSAS!$C$112 -> 0 | F11: =F9*PREMISSAS!$C$112 -> 0 | G11: =G9*PREMISSAS!$C$112 -> 0 | H11: =H9*PREMISSAS!$C$112 -> 0 | I11: =I9*PREMISSAS!$C$112 -> 0 | J11: =J9*PREMISSAS!$C$112 -> 0 | K11: =K9*PREMISSAS!$C$112 -> 0 | L11: =L9*PREMISSAS!$C$112 -> 0 | ... Y11: =Y9*PREMISSAS!$C$112 -> 0
B12: PIS/COFINS líquidos (biochar + carbono) | C12: max(7+8-10-11,0) + carbono(4×alíquota) | D12: max(7+8-10-11,0) | E12: =MAX(E7+E8-E10-E11,0)+E4*(PREMISSAS!$C$109+PREMISSAS!$C$110) -> 0 | F12: =MAX(F7+F8-F10-F11,0)+F4*(PREMISSAS!$C$109+PREMISSAS!$C$110) -> 268006.77 | G12: =MAX(G7+G8-G10-G11,0)+G4*(PREMISSAS!$C$109+PREMISSAS!$C$110) -> 268006.77 | H12: =MAX(H7+H8-H10-H11,0)+H4*(PREMISSAS!$C$109+PREMISSAS!$C$110) -> 268006.77 | I12: =MAX(I7+I8-I10-I11,0)+I4*(PREMISSAS!$C$109+PREMISSAS!$C$110) -> 268006.77 | J12: =MAX(J7+J8-J10-J11,0)+J4*(PREMISSAS!$C$109+PREMISSAS!$C$110) -> 268006.77 | K12: =MAX(K7+K8-K10-K11,0)+K4*(PREMISSAS!$C$109+PREMISSAS!$C$110) -> 268006.77 | L12: =MAX(L7+L8-L10-L11,0)+L4*(PREMISSAS!$C$109+PREMISSAS!$C$110) -> 268006.77 | ... Y12: =MAX(Y7+Y8-Y10-Y11,0)+Y4*(PREMISSAS!$C$109+PREMISSAS!$C$110) -> 268006.77
B13: Lucro antes de IRPJ/CSLL | C13: DRE_FCL | D13: equivale ao EBIT no modelo atual | E13: =DRE_FCL!E11 -> 0 | F13: =DRE_FCL!F11 -> 939734.97 | G13: =DRE_FCL!G11 -> 917634.97 | H13: =DRE_FCL!H11 -> 895534.97 | I13: =DRE_FCL!I11 -> 873434.97 | J13: =DRE_FCL!J11 -> 851334.97 | K13: =DRE_FCL!K11 -> 829234.97 | L13: =DRE_FCL!L11 -> 807134.97 | ... Y13: =DRE_FCL!Y11 -> 740834.97
B14: Adicoes fiscais | C14: PREMISSAS | D14: ajuste manual | E14: =PREMISSAS!$C$120 -> 0 | F14: =PREMISSAS!$C$120 -> 0 | G14: =PREMISSAS!$C$120 -> 0 | H14: =PREMISSAS!$C$120 -> 0 | I14: =PREMISSAS!$C$120 -> 0 | J14: =PREMISSAS!$C$120 -> 0 | K14: =PREMISSAS!$C$120 -> 0 | L14: =PREMISSAS!$C$120 -> 0 | ... Y14: =PREMISSAS!$C$120 -> 0
B15: Exclusoes fiscais | C15: PREMISSAS | D15: ajuste manual | E15: =PREMISSAS!$C$121 -> 0 | F15: =PREMISSAS!$C$121 -> 0 | G15: =PREMISSAS!$C$121 -> 0 | H15: =PREMISSAS!$C$121 -> 0 | I15: =PREMISSAS!$C$121 -> 0 | J15: =PREMISSAS!$C$121 -> 0 | K15: =PREMISSAS!$C$121 -> 0 | L15: =PREMISSAS!$C$121 -> 0 | ... Y15: =PREMISSAS!$C$121 -> 0
B16: Lucro real antes compensacoes | C16: Calculado | D16: 13+14-15 | E16: =E13+E14-E15 -> 0 | F16: =F13+F14-F15 -> 939734.97 | G16: =G13+G14-G15 -> 917634.97 | H16: =H13+H14-H15 -> 895534.97 | I16: =I13+I14-I15 -> 873434.97 | J16: =J13+J14-J15 -> 851334.97 | K16: =K13+K14-K15 -> 829234.97 | L16: =L13+L14-L15 -> 807134.97 | ... Y16: =Y13+Y14-Y15 -> 740834.97
B17: Prejuizo fiscal acumulado inicial | C17: Calculado | D17: saldo do ano anterior | E17: 0 | F17: =E26 -> 0 | G17: =F26 -> 0 | H17: =G26 -> 0 | I17: =H26 -> 0 | J17: =I26 -> 0 | K17: =J26 -> 0 | L17: =K26 -> 0 | M17: =L26 -> 0 | ... Y17: =X26 -> 0
B18: Compensacao de prejuizo fiscal | C18: Calculado | D18: limitada a 30% | E18: =IF(E16>0,MIN(E17,E16*PREMISSAS!$C$118),0) -> 0 | F18: =IF(F16>0,MIN(F17,F16*PREMISSAS!$C$118),0) -> 0 | G18: =IF(G16>0,MIN(G17,G16*PREMISSAS!$C$118),0) -> 0 | H18: =IF(H16>0,MIN(H17,H16*PREMISSAS!$C$118),0) -> 0 | I18: =IF(I16>0,MIN(I17,I16*PREMISSAS!$C$118),0) -> 0 | J18: =IF(J16>0,MIN(J17,J16*PREMISSAS!$C$118),0) -> 0 | K18: =IF(K16>0,MIN(K17,K16*PREMISSAS!$C$118),0) -> 0 | L18: =IF(L16>0,MIN(L17,L16*PREMISSAS!$C$118),0) -> 0 | ... Y18: =IF(Y16>0,MIN(Y17,Y16*PREMISSAS!$C$118),0) -> 0
B19: Base IRPJ | C19: Calculado | D19: 16-18 | E19: =MAX(E16-E18,0) -> 0 | F19: =MAX(F16-F18,0) -> 939734.97 | G19: =MAX(G16-G18,0) -> 917634.97 | H19: =MAX(H16-H18,0) -> 895534.97 | I19: =MAX(I16-I18,0) -> 873434.97 | J19: =MAX(J16-J18,0) -> 851334.97 | K19: =MAX(K16-K18,0) -> 829234.97 | L19: =MAX(L16-L18,0) -> 807134.97 | ... Y19: =MAX(Y16-Y18,0) -> 740834.97
B20: IRPJ 15% | C20: Calculado | D20: 19 x aliquota | E20: =E19*PREMISSAS!$C$114 -> 0 | F20: =F19*PREMISSAS!$C$114 -> 140960.25 | G20: =G19*PREMISSAS!$C$114 -> 137645.25 | H20: =H19*PREMISSAS!$C$114 -> 134330.25 | I20: =I19*PREMISSAS!$C$114 -> 131015.25 | J20: =J19*PREMISSAS!$C$114 -> 127700.25 | K20: =K19*PREMISSAS!$C$114 -> 124385.25 | L20: =L19*PREMISSAS!$C$114 -> 121070.25 | ... Y20: =Y19*PREMISSAS!$C$114 -> 111125.25
B21: Adicional IRPJ 10% | C21: Calculado | D21: base acima do limite anual | E21: =MAX(E19-PREMISSAS!$C$116,0)*PREMISSAS!$C$115 -> 0 | F21: =MAX(F19-PREMISSAS!$C$116,0)*PREMISSAS!$C$115 -> 69973.497 | G21: =MAX(G19-PREMISSAS!$C$116,0)*PREMISSAS!$C$115 -> 67763.497 | H21: =MAX(H19-PREMISSAS!$C$116,0)*PREMISSAS!$C$115 -> 65553.497 | I21: =MAX(I19-PREMISSAS!$C$116,0)*PREMISSAS!$C$115 -> 63343.497 | J21: =MAX(J19-PREMISSAS!$C$116,0)*PREMISSAS!$C$115 -> 61133.497 | K21: =MAX(K19-PREMISSAS!$C$116,0)*PREMISSAS!$C$115 -> 58923.497 | L21: =MAX(L19-PREMISSAS!$C$116,0)*PREMISSAS!$C$115 -> 56713.497 | ... Y21: =MAX(Y19-PREMISSAS!$C$116,0)*PREMISSAS!$C$115 -> 50083.497
B22: Base negativa CSLL inicial | C22: Calculado | D22: saldo do ano anterior | E22: 0 | F22: =E27 -> 0 | G22: =F27 -> 0 | H22: =G27 -> 0 | I22: =H27 -> 0 | J22: =I27 -> 0 | K22: =J27 -> 0 | L22: =K27 -> 0 | M22: =L27 -> 0 | ... Y22: =X27 -> 0
B23: Compensacao base negativa CSLL | C23: Calculado | D23: limitada a 30% | E23: =IF(E16>0,MIN(E22,E16*PREMISSAS!$C$119),0) -> 0 | F23: =IF(F16>0,MIN(F22,F16*PREMISSAS!$C$119),0) -> 0 | G23: =IF(G16>0,MIN(G22,G16*PREMISSAS!$C$119),0) -> 0 | H23: =IF(H16>0,MIN(H22,H16*PREMISSAS!$C$119),0) -> 0 | I23: =IF(I16>0,MIN(I22,I16*PREMISSAS!$C$119),0) -> 0 | J23: =IF(J16>0,MIN(J22,J16*PREMISSAS!$C$119),0) -> 0 | K23: =IF(K16>0,MIN(K22,K16*PREMISSAS!$C$119),0) -> 0 | L23: =IF(L16>0,MIN(L22,L16*PREMISSAS!$C$119),0) -> 0 | ... Y23: =IF(Y16>0,MIN(Y22,Y16*PREMISSAS!$C$119),0) -> 0
B24: Base CSLL | C24: Calculado | D24: 16-23 | E24: =MAX(E16-E23,0) -> 0 | F24: =MAX(F16-F23,0) -> 939734.97 | G24: =MAX(G16-G23,0) -> 917634.97 | H24: =MAX(H16-H23,0) -> 895534.97 | I24: =MAX(I16-I23,0) -> 873434.97 | J24: =MAX(J16-J23,0) -> 851334.97 | K24: =MAX(K16-K23,0) -> 829234.97 | L24: =MAX(L16-L23,0) -> 807134.97 | ... Y24: =MAX(Y16-Y23,0) -> 740834.97
B25: CSLL 9% | C25: Calculado | D25: 24 x aliquota | E25: =E24*PREMISSAS!$C$117 -> 0 | F25: =F24*PREMISSAS!$C$117 -> 84576.148 | G25: =G24*PREMISSAS!$C$117 -> 82587.148 | H25: =H24*PREMISSAS!$C$117 -> 80598.148 | I25: =I24*PREMISSAS!$C$117 -> 78609.148 | J25: =J24*PREMISSAS!$C$117 -> 76620.148 | K25: =K24*PREMISSAS!$C$117 -> 74631.148 | L25: =L24*PREMISSAS!$C$117 -> 72642.148 | ... Y25: =Y24*PREMISSAS!$C$117 -> 66675.148
B26: Prejuizo fiscal acumulado final | C26: Calculado | D26: saldo para o proximo ano | E26: =MAX(E17-E18,0)+MAX(-E16,0) -> 0 | F26: =MAX(F17-F18,0)+MAX(-F16,0) -> 0 | G26: =MAX(G17-G18,0)+MAX(-G16,0) -> 0 | H26: =MAX(H17-H18,0)+MAX(-H16,0) -> 0 | I26: =MAX(I17-I18,0)+MAX(-I16,0) -> 0 | J26: =MAX(J17-J18,0)+MAX(-J16,0) -> 0 | K26: =MAX(K17-K18,0)+MAX(-K16,0) -> 0 | L26: =MAX(L17-L18,0)+MAX(-L16,0) -> 0 | ... Y26: =MAX(Y17-Y18,0)+MAX(-Y16,0) -> 0
B27: Base negativa CSLL final | C27: Calculado | D27: saldo para o proximo ano | E27: =MAX(E22-E23,0)+MAX(-E16,0) -> 0 | F27: =MAX(F22-F23,0)+MAX(-F16,0) -> 0 | G27: =MAX(G22-G23,0)+MAX(-G16,0) -> 0 | H27: =MAX(H22-H23,0)+MAX(-H16,0) -> 0 | I27: =MAX(I22-I23,0)+MAX(-I16,0) -> 0 | J27: =MAX(J22-J23,0)+MAX(-J16,0) -> 0 | K27: =MAX(K22-K23,0)+MAX(-K16,0) -> 0 | L27: =MAX(L22-L23,0)+MAX(-L16,0) -> 0 | ... Y27: =MAX(Y22-Y23,0)+MAX(-Y16,0) -> 0
B28: TRIBUTOS TOTAIS | C28: Calculado | D28: 12 + 20 + 21 + 25 | E28: =E12+E20+E21+E25 -> 0 | F28: =F12+F20+F21+F25 -> 563516.66 | G28: =G12+G20+G21+G25 -> 556002.66 | H28: =H12+H20+H21+H25 -> 548488.66 | I28: =I12+I20+I21+I25 -> 540974.66 | J28: =J12+J20+J21+J25 -> 533460.66 | K28: =K12+K20+K21+K25 -> 525946.66 | L28: =L12+L20+L21+L25 -> 518432.66 | ... Y28: =Y12+Y20+Y21+Y25 -> 495890.66
B29: Aliquota efetiva s/ receita bruta | C29: Calculado | D29: 28 / 6 | E29: =IF(E6<>0,E28/E6,0) -> 0 | F29: =IF(F6<>0,F28/F6,0) -> 0.19449244 | G29: =IF(G6<>0,G28/G6,0) -> 0.19189906 | H29: =IF(H6<>0,H28/H6,0) -> 0.18930567 | I29: =IF(I6<>0,I28/I6,0) -> 0.18671228 | J29: =IF(J6<>0,J28/J6,0) -> 0.1841189 | K29: =IF(K6<>0,K28/K6,0) -> 0.18152551 | L29: =IF(L6<>0,L28/L6,0) -> 0.17893213 | ... Y29: =IF(Y6<>0,Y28/Y6,0) -> 0.17115197

Sheet OPEX
B1: OPEX | Custos Operacionais por Driver
B2: Estrutura separada por motor economico: por tonelada processada, por mes de campanha e fixos anuais de existencia do projeto.
B3: Item de Custo | C3: Classe | D3: Motor Economico | E3: 2026 | F3: 2027 | G3: 2028 | H3: 2029 | I3: 2030 | J3: 2031 | K3: 2032 | L3: 2033 | M3: 2034 | N3: 2035 | O3: 2036 | P3: 2037 | Q3: 2038 | R3: 2039 | S3: 2040 | T3: 2041 | U3: 2042 | V3: 2043 | W3: 2044 | X3: 2045 | Y3: 2046
B4: CUSTOS POR TONELADA PROCESSADA
B5: Energia eletrica variavel - somente meses com operacao | C5: Por tonelada processada | D5: Consumo kWh de processo/startup x tarifa efetiva; meses sem operacao nao geram consumo do projeto | E5: =IF(CÁLCULO!E4>0,(((CÁLCULO!E4*PREMISSAS!$C$48)+PREMISSAS!$C$45)*PREMISSAS!$C$78),0) -> 0 | F5: =IF(CÁLCULO!F4>0,(((CÁLCULO!F4*PREMISSAS!$C$48)+PREMISSAS!$C$45)*PREMISSAS!$C$78),0) -> 624196.09 | G5: =IF(CÁLCULO!G4>0,(((CÁLCULO!G4*PREMISSAS!$C$48)+PREMISSAS!$C$45)*PREMISSAS!$C$78),0) -> 624196.09 | H5: =IF(CÁLCULO!H4>0,(((CÁLCULO!H4*PREMISSAS!$C$48)+PREMISSAS!$C$45)*PREMISSAS!$C$78),0) -> 624196.09 | I5: =IF(CÁLCULO!I4>0,(((CÁLCULO!I4*PREMISSAS!$C$48)+PREMISSAS!$C$45)*PREMISSAS!$C$78),0) -> 624196.09 | J5: =IF(CÁLCULO!J4>0,(((CÁLCULO!J4*PREMISSAS!$C$48)+PREMISSAS!$C$45)*PREMISSAS!$C$78),0) -> 624196.09 | K5: =IF(CÁLCULO!K4>0,(((CÁLCULO!K4*PREMISSAS!$C$48)+PREMISSAS!$C$45)*PREMISSAS!$C$78),0) -> 624196.09 | L5: =IF(CÁLCULO!L4>0,(((CÁLCULO!L4*PREMISSAS!$C$48)+PREMISSAS!$C$45)*PREMISSAS!$C$78),0) -> 624196.09 | ... Y5: =IF(CÁLCULO!Y4>0,(((CÁLCULO!Y4*PREMISSAS!$C$48)+PREMISSAS!$C$45)*PREMISSAS!$C$78),0) -> 624196.09
B6: Logistica de coleta | C6: Por tonelada processada | D6: R$/t biomassa | E6: 0 | F6: =PREMISSAS!$C$53*CÁLCULO!F4 -> 141870.33 | G6: =PREMISSAS!$C$53*CÁLCULO!G4 -> 141870.33 | H6: =PREMISSAS!$C$53*CÁLCULO!H4 -> 141870.33 | I6: =PREMISSAS!$C$53*CÁLCULO!I4 -> 141870.33 | J6: =PREMISSAS!$C$53*CÁLCULO!J4 -> 141870.33 | K6: =PREMISSAS!$C$53*CÁLCULO!K4 -> 141870.33 | L6: =PREMISSAS!$C$53*CÁLCULO!L4 -> 141870.33 | M6: =PREMISSAS!$C$53*CÁLCULO!M4 -> 141870.33 | ... Y6: =PREMISSAS!$C$53*CÁLCULO!Y4 -> 141870.33
B7: Logistica de transporte | C7: Por tonelada processada | D7: R$/t biomassa | E7: 0 | F7: =PREMISSAS!$C$54*CÁLCULO!F4 -> 236450.55 | G7: =PREMISSAS!$C$54*CÁLCULO!G4 -> 236450.55 | H7: =PREMISSAS!$C$54*CÁLCULO!H4 -> 236450.55 | I7: =PREMISSAS!$C$54*CÁLCULO!I4 -> 236450.55 | J7: =PREMISSAS!$C$54*CÁLCULO!J4 -> 236450.55 | K7: =PREMISSAS!$C$54*CÁLCULO!K4 -> 236450.55 | L7: =PREMISSAS!$C$54*CÁLCULO!L4 -> 236450.55 | M7: =PREMISSAS!$C$54*CÁLCULO!M4 -> 236450.55 | ... Y7: =PREMISSAS!$C$54*CÁLCULO!Y4 -> 236450.55
B8: Big bags e embalagem | C8: Por tonelada processada | D8: R$/t biochar | E8: 0 | F8: =PREMISSAS!$C$57*CÁLCULO!F5 -> 25264.741 | G8: =PREMISSAS!$C$57*CÁLCULO!G5 -> 25264.741 | H8: =PREMISSAS!$C$57*CÁLCULO!H5 -> 25264.741 | I8: =PREMISSAS!$C$57*CÁLCULO!I5 -> 25264.741 | J8: =PREMISSAS!$C$57*CÁLCULO!J5 -> 25264.741 | K8: =PREMISSAS!$C$57*CÁLCULO!K5 -> 25264.741 | L8: =PREMISSAS!$C$57*CÁLCULO!L5 -> 25264.741 | M8: =PREMISSAS!$C$57*CÁLCULO!M5 -> 25264.741 | ... Y8: =PREMISSAS!$C$57*CÁLCULO!Y5 -> 25264.741
B9: Material de laboratorio | C9: Por tonelada processada | D9: R$/t biochar | E9: 0 | F9: =PREMISSAS!$C$58*CÁLCULO!F5 -> 36094.177 | G9: =PREMISSAS!$C$58*CÁLCULO!G5 -> 36094.177 | H9: =PREMISSAS!$C$58*CÁLCULO!H5 -> 36094.177 | I9: =PREMISSAS!$C$58*CÁLCULO!I5 -> 36094.177 | J9: =PREMISSAS!$C$58*CÁLCULO!J5 -> 36094.177 | K9: =PREMISSAS!$C$58*CÁLCULO!K5 -> 36094.177 | L9: =PREMISSAS!$C$58*CÁLCULO!L5 -> 36094.177 | M9: =PREMISSAS!$C$58*CÁLCULO!M5 -> 36094.177 | ... Y9: =PREMISSAS!$C$58*CÁLCULO!Y5 -> 36094.177
B10: SUBTOTAL CUSTOS POR TONELADA | E10: 0 | F10: =SUM(F5:F9) -> 1063875.9 | G10: =SUM(G5:G9) -> 1063875.9 | H10: =SUM(H5:H9) -> 1063875.9 | I10: =SUM(I5:I9) -> 1063875.9 | J10: =SUM(J5:J9) -> 1063875.9 | K10: =SUM(K5:K9) -> 1063875.9 | L10: =SUM(L5:L9) -> 1063875.9 | M10: =SUM(M5:M9) -> 1063875.9 | ... Y10: =SUM(Y5:Y9) -> 1063875.9
B11: CUSTOS POR MES DE CAMPANHA
B12: Mao de obra operacional | C12: Por mes de campanha | D12: Operadores x salario x meses de calendario da campanha | E12: 0 | F12: =PREMISSAS!$C$51*PREMISSAS!$C$50*CÁLCULO!F10 -> 354675.83 | G12: =PREMISSAS!$C$51*PREMISSAS!$C$50*CÁLCULO!G10 -> 354675.83 | H12: =PREMISSAS!$C$51*PREMISSAS!$C$50*CÁLCULO!H10 -> 354675.83 | I12: =PREMISSAS!$C$51*PREMISSAS!$C$50*CÁLCULO!I10 -> 354675.83 | J12: =PREMISSAS!$C$51*PREMISSAS!$C$50*CÁLCULO!J10 -> 354675.83 | K12: =PREMISSAS!$C$51*PREMISSAS!$C$50*CÁLCULO!K10 -> 354675.83 | L12: =PREMISSAS!$C$51*PREMISSAS!$C$50*CÁLCULO!L10 -> 354675.83 | M12: =PREMISSAS!$C$51*PREMISSAS!$C$50*CÁLCULO!M10 -> 354675.83 | ... Y12: =PREMISSAS!$C$51*PREMISSAS!$C$50*CÁLCULO!Y10 -> 354675.83
B13: O&M reator BST-30 | C13: O&M progressivo | D13: Ano n = MIN(n,10) x taxa ano 1 x CAPEX do reator BST-30; n=1 em 2027. Sem prorrata por meses de campanha. | E13: 0 | F13: =IF(CÁLCULO!F4>0,PREMISSAS!$C$52*MIN(1,10)*CAPEX!$C$6,0) -> 22100 | G13: =IF(CÁLCULO!G4>0,PREMISSAS!$C$52*MIN(2,10)*CAPEX!$C$6,0) -> 44200 | H13: =IF(CÁLCULO!H4>0,PREMISSAS!$C$52*MIN(3,10)*CAPEX!$C$6,0) -> 66300 | I13: =IF(CÁLCULO!I4>0,PREMISSAS!$C$52*MIN(4,10)*CAPEX!$C$6,0) -> 88400 | J13: =IF(CÁLCULO!J4>0,PREMISSAS!$C$52*MIN(5,10)*CAPEX!$C$6,0) -> 110500 | K13: =IF(CÁLCULO!K4>0,PREMISSAS!$C$52*MIN(6,10)*CAPEX!$C$6,0) -> 132600 | L13: =IF(CÁLCULO!L4>0,PREMISSAS!$C$52*MIN(7,10)*CAPEX!$C$6,0) -> 154700 | M13: =IF(CÁLCULO!M4>0,PREMISSAS!$C$52*MIN(8,10)*CAPEX!$C$6,0) -> 176800 | N13: =IF(CÁLCULO!N4>0,PREMISSAS!$C$52*MIN(9,10)*CAPEX!$C$6,0) -> 198900 | O13: =IF(CÁLCULO!O4>0,PREMISSAS!$C$52*MIN(10,10)*CAPEX!$C$6,0) -> 221000 | P13: =IF(CÁLCULO!P4>0,PREMISSAS!$C$52*MIN(11,10)*CAPEX!$C$6,0) -> 221000 | Q13: =IF(CÁLCULO!Q4>0,PREMISSAS!$C$52*MIN(12,10)*CAPEX!$C$6,0) -> 221000 | R13: =IF(CÁLCULO!R4>0,PREMISSAS!$C$52*MIN(13,10)*CAPEX!$C$6,0) -> 221000 | S13: =IF(CÁLCULO!S4>0,PREMISSAS!$C$52*MIN(14,10)*CAPEX!$C$6,0) -> 221000 | T13: =IF(CÁLCULO!T4>0,PREMISSAS!$C$52*MIN(15,10)*CAPEX!$C$6,0) -> 221000 | U13: =IF(CÁLCULO!U4>0,PREMISSAS!$C$52*MIN(16,10)*CAPEX!$C$6,0) -> 221000 | V13: =IF(CÁLCULO!V4>0,PREMISSAS!$C$52*MIN(17,10)*CAPEX!$C$6,0) -> 221000 | W13: =IF(CÁLCULO!W4>0,PREMISSAS!$C$52*MIN(18,10)*CAPEX!$C$6,0) -> 221000 | X13: =IF(CÁLCULO!X4>0,PREMISSAS!$C$52*MIN(19,10)*CAPEX!$C$6,0) -> 221000 | Y13: =IF(CÁLCULO!Y4>0,PREMISSAS!$C$52*MIN(20,10)*CAPEX!$C$6,0) -> 221000
B14: SUBTOTAL CUSTOS POR MES DE CAMPANHA | E14: 0 | F14: =SUM(F12:F13) -> 376775.83 | G14: =SUM(G12:G13) -> 398875.83 | H14: =SUM(H12:H13) -> 420975.83 | I14: =SUM(I12:I13) -> 443075.83 | J14: =SUM(J12:J13) -> 465175.83 | K14: =SUM(K12:K13) -> 487275.83 | L14: =SUM(L12:L13) -> 509375.83 | M14: =SUM(M12:M13) -> 531475.83 | ... Y14: =SUM(Y12:Y13) -> 575675.83
B15: CUSTOS FIXOS ANUAIS DE EXISTENCIA
B16: Demanda contratada Cemig A4 Verde 360 kW - 12 meses | C16: Fixo anual | D16: Custo fixo do projeto: demanda unica contratada x 12 meses, inclusive meses sem operacao | E16: =IF(CÁLCULO!E4>0,PREMISSAS!$C$79*PREMISSAS!$C$105,0) -> 0 | F16: =IF(CÁLCULO!F4>0,PREMISSAS!$C$79*PREMISSAS!$C$105,0) -> 129214.79 | G16: =IF(CÁLCULO!G4>0,PREMISSAS!$C$79*PREMISSAS!$C$105,0) -> 129214.79 | H16: =IF(CÁLCULO!H4>0,PREMISSAS!$C$79*PREMISSAS!$C$105,0) -> 129214.79 | I16: =IF(CÁLCULO!I4>0,PREMISSAS!$C$79*PREMISSAS!$C$105,0) -> 129214.79 | J16: =IF(CÁLCULO!J4>0,PREMISSAS!$C$79*PREMISSAS!$C$105,0) -> 129214.79 | K16: =IF(CÁLCULO!K4>0,PREMISSAS!$C$79*PREMISSAS!$C$105,0) -> 129214.79 | L16: =IF(CÁLCULO!L4>0,PREMISSAS!$C$79*PREMISSAS!$C$105,0) -> 129214.79 | ... Y16: =IF(CÁLCULO!Y4>0,PREMISSAS!$C$79*PREMISSAS!$C$105,0) -> 129214.79
B17: Auditoria e verificacao anual | C17: Fixo anual | D17: Obrigacao anual de conformidade / verificacao | E17: 0 | F17: =PREMISSAS!$C$55 -> 100000 | G17: =PREMISSAS!$C$55 -> 100000 | H17: =PREMISSAS!$C$55 -> 100000 | I17: =PREMISSAS!$C$55 -> 100000 | J17: =PREMISSAS!$C$55 -> 100000 | K17: =PREMISSAS!$C$55 -> 100000 | L17: =PREMISSAS!$C$55 -> 100000 | M17: =PREMISSAS!$C$55 -> 100000 | ... Y17: =PREMISSAS!$C$55 -> 100000
B18: Renovacao LCA + relatorio | C18: Fixo anual | D18: Obrigacao anual de conformidade / relatorio | E18: 0 | F18: =PREMISSAS!$C$56 -> 35000 | G18: =PREMISSAS!$C$56 -> 35000 | H18: =PREMISSAS!$C$56 -> 35000 | I18: =PREMISSAS!$C$56 -> 35000 | J18: =PREMISSAS!$C$56 -> 35000 | K18: =PREMISSAS!$C$56 -> 35000 | L18: =PREMISSAS!$C$56 -> 35000 | M18: =PREMISSAS!$C$56 -> 35000 | ... Y18: =PREMISSAS!$C$56 -> 35000
B19: Treinamento e outros fixos | C19: Fixo anual | D19: Custo recorrente de existencia do projeto | E19: 0 | F19: =PREMISSAS!$C$59 -> 10000 | G19: =PREMISSAS!$C$59 -> 10000 | H19: =PREMISSAS!$C$59 -> 10000 | I19: =PREMISSAS!$C$59 -> 10000 | J19: =PREMISSAS!$C$59 -> 10000 | K19: =PREMISSAS!$C$59 -> 10000 | L19: =PREMISSAS!$C$59 -> 10000 | M19: =PREMISSAS!$C$59 -> 10000 | ... Y19: =PREMISSAS!$C$59 -> 10000
B20: Diesel startup | C20: Por ciclo (variável com biomassa) | D20: Ciclos/ano × L/ciclo × R$/L via PREMISSAS!C96=C27×C94×C95. Escala com biomassa através de C27 (ciclos/ano). Classificado aqui por conveniência; motor econômico é variável com operação. | E20: 0 | F20: =PREMISSAS!$C$82 -> 19669 | G20: =PREMISSAS!$C$82 -> 19669 | H20: =PREMISSAS!$C$82 -> 19669 | I20: =PREMISSAS!$C$82 -> 19669 | J20: =PREMISSAS!$C$82 -> 19669 | K20: =PREMISSAS!$C$82 -> 19669 | L20: =PREMISSAS!$C$82 -> 19669 | M20: =PREMISSAS!$C$82 -> 19669 | ... Y20: =PREMISSAS!$C$82 -> 19669
B21: SUBTOTAL FIXOS ANUAIS | E21: 0 | F21: =SUM(F16:F20) -> 293883.79 | G21: =SUM(G16:G20) -> 293883.79 | H21: =SUM(H16:H20) -> 293883.79 | I21: =SUM(I16:I20) -> 293883.79 | J21: =SUM(J16:J20) -> 293883.79 | K21: =SUM(K16:K20) -> 293883.79 | L21: =SUM(L16:L20) -> 293883.79 | M21: =SUM(M16:M20) -> 293883.79 | ... Y21: =SUM(Y16:Y20) -> 293883.79
B22: TOTAL OPEX ANUAL | E22: 0 | F22: =F10+F14+F21 -> 1734535.5 | G22: =G10+G14+G21 -> 1756635.5 | H22: =H10+H14+H21 -> 1778735.5 | I22: =I10+I14+I21 -> 1800835.5 | J22: =J10+J14+J21 -> 1822935.5 | K22: =K10+K14+K21 -> 1845035.5 | L22: =L10+L14+L21 -> 1867135.5 | M22: =M10+M14+M21 -> 1889235.5 | ... Y22: =Y10+Y14+Y21 -> 1933435.5
B25: Tabela O&M progressivo do reator BST-30
B26: Ano | C26: Ano operacional | D26: Taxa O&M | E26: Base de c?lculo | F26: Valor O&M (R$) | G26: Regra aplicada
B27: 2027 | C27: 1 | D27: =MIN(C27,10)*PREMISSAS!$C$52 -> 0.01 | E27: =CAPEX!$C$6 -> 2210000 | F27: =OPEX!F$13 -> 22100 | G27: =TEXT(D27,"0%")&" x CAPEX do reator" -> 1% x CAPEX do reator
B28: 2028 | C28: 2 | D28: =MIN(C28,10)*PREMISSAS!$C$52 -> 0.02 | E28: =CAPEX!$C$6 -> 2210000 | F28: =OPEX!G$13 -> 44200 | G28: =TEXT(D28,"0%")&" x CAPEX do reator" -> 2% x CAPEX do reator
B29: 2029 | C29: 3 | D29: =MIN(C29,10)*PREMISSAS!$C$52 -> 0.03 | E29: =CAPEX!$C$6 -> 2210000 | F29: =OPEX!H$13 -> 66300 | G29: =TEXT(D29,"0%")&" x CAPEX do reator" -> 3% x CAPEX do reator
B30: 2030 | C30: 4 | D30: =MIN(C30,10)*PREMISSAS!$C$52 -> 0.04 | E30: =CAPEX!$C$6 -> 2210000 | F30: =OPEX!I$13 -> 88400 | G30: =TEXT(D30,"0%")&" x CAPEX do reator" -> 4% x CAPEX do reator
B31: 2031 | C31: 5 | D31: =MIN(C31,10)*PREMISSAS!$C$52 -> 0.05 | E31: =CAPEX!$C$6 -> 2210000 | F31: =OPEX!J$13 -> 110500 | G31: =TEXT(D31,"0%")&" x CAPEX do reator" -> 5% x CAPEX do reator
B32: 2032 | C32: 6 | D32: =MIN(C32,10)*PREMISSAS!$C$52 -> 0.06 | E32: =CAPEX!$C$6 -> 2210000 | F32: =OPEX!K$13 -> 132600 | G32: =TEXT(D32,"0%")&" x CAPEX do reator" -> 6% x CAPEX do reator
B33: 2033 | C33: 7 | D33: =MIN(C33,10)*PREMISSAS!$C$52 -> 0.07 | E33: =CAPEX!$C$6 -> 2210000 | F33: =OPEX!L$13 -> 154700 | G33: =TEXT(D33,"0%")&" x CAPEX do reator" -> 7% x CAPEX do reator
B34: 2034 | C34: 8 | D34: =MIN(C34,10)*PREMISSAS!$C$52 -> 0.08 | E34: =CAPEX!$C$6 -> 2210000 | F34: =OPEX!M$13 -> 176800 | G34: =TEXT(D34,"0%")&" x CAPEX do reator" -> 8% x CAPEX do reator
B35: 2035 | C35: 9 | D35: =MIN(C35,10)*PREMISSAS!$C$52 -> 0.09 | E35: =CAPEX!$C$6 -> 2210000 | F35: =OPEX!N$13 -> 198900 | G35: =TEXT(D35,"0%")&" x CAPEX do reator" -> 9% x CAPEX do reator
B36: 2036 | C36: 10 | D36: =MIN(C36,10)*PREMISSAS!$C$52 -> 0.1 | E36: =CAPEX!$C$6 -> 2210000 | F36: =OPEX!O$13 -> 221000 | G36: =TEXT(D36,"0%")&" x CAPEX do reator" -> 10% x CAPEX do reator
B37: 2037 | C37: 11 | D37: =MIN(C37,10)*PREMISSAS!$C$52 -> 0.1 | E37: =CAPEX!$C$6 -> 2210000 | F37: =OPEX!P$13 -> 221000 | G37: =TEXT(D37,"0%")&" x CAPEX do reator" -> 10% x CAPEX do reator
B38: 2038 | C38: 12 | D38: =MIN(C38,10)*PREMISSAS!$C$52 -> 0.1 | E38: =CAPEX!$C$6 -> 2210000 | F38: =OPEX!Q$13 -> 221000 | G38: =TEXT(D38,"0%")&" x CAPEX do reator" -> 10% x CAPEX do reator
B39: 2039 | C39: 13 | D39: =MIN(C39,10)*PREMISSAS!$C$52 -> 0.1 | E39: =CAPEX!$C$6 -> 2210000 | F39: =OPEX!R$13 -> 221000 | G39: =TEXT(D39,"0%")&" x CAPEX do reator" -> 10% x CAPEX do reator
B40: 2040 | C40: 14 | D40: =MIN(C40,10)*PREMISSAS!$C$52 -> 0.1 | E40: =CAPEX!$C$6 -> 2210000 | F40: =OPEX!S$13 -> 221000 | G40: =TEXT(D40,"0%")&" x CAPEX do reator" -> 10% x CAPEX do reator
B41: 2041 | C41: 15 | D41: =MIN(C41,10)*PREMISSAS!$C$52 -> 0.1 | E41: =CAPEX!$C$6 -> 2210000 | F41: =OPEX!T$13 -> 221000 | G41: =TEXT(D41,"0%")&" x CAPEX do reator" -> 10% x CAPEX do reator
B42: 2042 | C42: 16 | D42: =MIN(C42,10)*PREMISSAS!$C$52 -> 0.1 | E42: =CAPEX!$C$6 -> 2210000 | F42: =OPEX!U$13 -> 221000 | G42: =TEXT(D42,"0%")&" x CAPEX do reator" -> 10% x CAPEX do reator
...

Sheet DRE_FCL
B1: DRE SIMPLIFICADA + FLUXO DE CAIXA LIVRE
B2: Estrutura auditavel: cada linha referencia aba-fonte; tributos detalhados na aba TRIBUTOS.
B3: Item | C3: Origem | D3: Referência | E3: 2026 | F3: 2027 | G3: 2028 | H3: 2029 | I3: 2030 | J3: 2031 | K3: 2032 | L3: 2033 | M3: 2034 | N3: 2035 | O3: 2036 | P3: 2037 | Q3: 2038 | R3: 2039 | S3: 2040 | T3: 2041 | U3: 2042 | V3: 2043 | W3: 2044 | X3: 2045 | Y3: 2046
B4: (–) CAPEX — Investimento inicial | C4: CAPEX | D4: CAPEX!$C$15 | E4: =-CAPEX!$C$16 -> -5498000 | F4: 0 | G4: 0 | H4: 0 | I4: 0 | J4: 0 | K4: 0 | L4: 0 | M4: 0 | N4: 0 | O4: 0 | P4: 0 | Q4: 0 | R4: 0 | S4: 0 | T4: 0 | U4: 0 | V4: 0 | W4: 0 | X4: 0 | Y4: 0
B5: (+) Receita bruta total | C5: RECEITA | D5: → RECEITA!5 | E5: 0 | F5: =RECEITA!F5 -> 2897370.5 | G5: =RECEITA!G5 -> 2897370.5 | H5: =RECEITA!H5 -> 2897370.5 | I5: =RECEITA!I5 -> 2897370.5 | J5: =RECEITA!J5 -> 2897370.5 | K5: =RECEITA!K5 -> 2897370.5 | L5: =RECEITA!L5 -> 2897370.5 | M5: =RECEITA!M5 -> 2897370.5 | ... Y5: =RECEITA!Y5 -> 2897370.5
B6: (–) Fee Astra Carbon | C6: RECEITA | D6: → RECEITA!6 | E6: 0 | F6: =RECEITA!F6 -> 0 | G6: =RECEITA!G6 -> 0 | H6: =RECEITA!H6 -> 0 | I6: =RECEITA!I6 -> 0 | J6: =RECEITA!J6 -> 0 | K6: =RECEITA!K6 -> 0 | L6: =RECEITA!L6 -> 0 | M6: =RECEITA!M6 -> 0 | ... Y6: =RECEITA!Y6 -> 0
B7: (–) Total OPEX | C7: OPEX | D7: OPEX!22 | E7: 0 | F7: =-OPEX!F22 -> -1734535.5 | G7: =-OPEX!G22 -> -1756635.5 | H7: =-OPEX!H22 -> -1778735.5 | I7: =-OPEX!I22 -> -1800835.5 | J7: =-OPEX!J22 -> -1822935.5 | K7: =-OPEX!K22 -> -1845035.5 | L7: =-OPEX!L22 -> -1867135.5 | M7: =-OPEX!M22 -> -1889235.5 | ... Y7: =-OPEX!Y22 -> -1933435.5
B8: EBITDA | C8: Calculado | D8: bruta+astra+opex | E8: 0 | F8: =F5+F6+F7 -> 1162835 | G8: =G5+G6+G7 -> 1140735 | H8: =H5+H6+H7 -> 1118635 | I8: =I5+I6+I7 -> 1096535 | J8: =J5+J6+J7 -> 1074435 | K8: =K5+K6+K7 -> 1052335 | L8: =L5+L6+L7 -> 1030235 | M8: =M5+M6+M7 -> 1008135 | ... Y8: =Y5+Y6+Y7 -> 963934.97
B9: Margem EBITDA (%) | D9: EBITDA/Receita | E9: 0 | F9: =IF(F5<>0,F8/F5,0) -> 0.40134149 | G9: =IF(G5<>0,G8/G5,0) -> 0.39371388 | H9: =IF(H5<>0,H8/H5,0) -> 0.38608627 | I9: =IF(I5<>0,I8/I5,0) -> 0.37845867 | J9: =IF(J5<>0,J8/J5,0) -> 0.37083106 | K9: =IF(K5<>0,K8/K5,0) -> 0.36320346 | L9: =IF(L5<>0,L8/L5,0) -> 0.35557585 | M9: =IF(M5<>0,M8/M5,0) -> 0.34794824 | ... Y9: =IF(Y5<>0,Y8/Y5,0) -> 0.33269303
B10: (–) Depreciação | C10: CAPEX | D10: → CAPEX!23 | E10: =-CAPEX!E24 -> 0 | F10: =-CAPEX!F24 -> -223100 | G10: =-CAPEX!G24 -> -223100 | H10: =-CAPEX!H24 -> -223100 | I10: =-CAPEX!I24 -> -223100 | J10: =-CAPEX!J24 -> -223100 | K10: =-CAPEX!K24 -> -223100 | L10: =-CAPEX!L24 -> -223100 | ... Y10: =-CAPEX!Y24 -> -223100
B11: EBIT | C11: Calculado | D11: EBITDA−D&A | E11: 0 | F11: =F8+F10 -> 939734.97 | G11: =G8+G10 -> 917634.97 | H11: =H8+H10 -> 895534.97 | I11: =I8+I10 -> 873434.97 | J11: =J8+J10 -> 851334.97 | K11: =K8+K10 -> 829234.97 | L11: =L8+L10 -> 807134.97 | M11: =M8+M10 -> 785034.97 | ... Y11: =Y8+Y10 -> 740834.97
B12: (-) Tributos (PIS/COFINS + IRPJ/CSLL) | C12: TRIBUTOS | D12: -> TRIBUTOS!28 | E12: =-TRIBUTAÇÃO!E28 -> 0 | F12: =-TRIBUTAÇÃO!F28 -> -563516.66 | G12: =-TRIBUTAÇÃO!G28 -> -556002.66 | H12: =-TRIBUTAÇÃO!H28 -> -548488.66 | I12: =-TRIBUTAÇÃO!I28 -> -540974.66 | J12: =-TRIBUTAÇÃO!J28 -> -533460.66 | K12: =-TRIBUTAÇÃO!K28 -> -525946.66 | L12: =-TRIBUTAÇÃO!L28 -> -518432.66 | ... Y12: =-TRIBUTAÇÃO!Y28 -> -495890.66
B13: Lucro Líquido | C13: Calculado | D13: EBIT−IR | E13: 0 | F13: =F11+F12 -> 376218.31 | G13: =G11+G12 -> 361632.31 | H13: =H11+H12 -> 347046.31 | I13: =I11+I12 -> 332460.31 | J13: =J11+J12 -> 317874.31 | K13: =K11+K12 -> 303288.31 | L13: =L11+L12 -> 288702.31 | M13: =M11+M12 -> 274116.31 | ... Y13: =Y11+Y12 -> 244944.31
B14: (+) Add-back depreciação | C14: Não caixa | D14: reverso D&A | E14: 0 | F14: =-F10 -> 223100 | G14: =-G10 -> 223100 | H14: =-H10 -> 223100 | I14: =-I10 -> 223100 | J14: =-J10 -> 223100 | K14: =-K10 -> 223100 | L14: =-L10 -> 223100 | M14: =-M10 -> 223100 | ... Y14: =-Y10 -> 223100
B15: FCL — FLUXO DE CAIXA LIVRE | C15: Calculado | D15: CAPEX+LL+D&A | E15: =E4+E13+E14 -> -5498000 | F15: =F4+F13+F14 -> 599318.31 | G15: =G4+G13+G14 -> 584732.31 | H15: =H4+H13+H14 -> 570146.31 | I15: =I4+I13+I14 -> 555560.31 | J15: =J4+J13+J14 -> 540974.31 | K15: =K4+K13+K14 -> 526388.31 | L15: =L4+L13+L14 -> 511802.31 | ... Y15: =Y4+Y13+Y14 -> 468044.31
B16: FCL Acumulado | D16: running sum | E16: =E15 -> -5498000 | F16: =E16+F15 -> -4898681.7 | G16: =F16+G15 -> -4313949.4 | H16: =G16+H15 -> -3743803.1 | I16: =H16+I15 -> -3188242.7 | J16: =I16+J15 -> -2647268.4 | K16: =J16+K15 -> -2120880.1 | L16: =K16+L15 -> -1609077.8 | M16: =L16+M15 -> -1111861.5 | ... Y16: =X16+Y15 -> 4519256.3
B17: Delta Capital de Giro | C17: WC recebíveis | D17: prazo×rec/12 | E17: =IF(PREMISSAS!$C$107=1,-(RECEITA!F5/12)*PREMISSAS!$C$106,0) -> 0 | F17: 0 | G17: 0 | H17: 0 | I17: 0 | J17: 0 | K17: 0 | L17: 0 | M17: 0 | N17: 0 | O17: 0 | P17: 0 | Q17: 0 | R17: 0 | S17: 0 | T17: 0 | U17: 0 | V17: 0 | W17: 0 | X17: 0 | Y17: =IF(PREMISSAS!$C$107=1,(RECEITA!F5/12)*PREMISSAS!$C$106,0) -> 0
B18: FCL incluindo Capital de Giro | C18: Calculado | D18: FCL+Delta WC | E18: =E15+E17 -> -5498000 | F18: =F15+F17 -> 599318.31 | G18: =G15+G17 -> 584732.31 | H18: =H15+H17 -> 570146.31 | I18: =I15+I17 -> 555560.31 | J18: =J15+J17 -> 540974.31 | K18: =K15+K17 -> 526388.31 | L18: =L15+L17 -> 511802.31 | ... Y18: =Y15+Y17 -> 468044.31
B19: FCL Acumulado c/ Capital de Giro | D19: running sum | E19: =E18 -> -5498000 | F19: =E19+F18 -> -4898681.7 | G19: =F19+G18 -> -4313949.4 | H19: =G19+H18 -> -3743803.1 | I19: =H19+I18 -> -3188242.7 | J19: =I19+J18 -> -2647268.4 | K19: =J19+K18 -> -2120880.1 | L19: =K19+L18 -> -1609077.8 | M19: =L19+M18 -> -1111861.5 | ... Y19: =X19+Y18 -> 4519256.3

Sheet ENERGIA
B1: ENERGIA | C1: Caso-base eletrico unico: Cemig A4 Verde 360 kW, cominuicao fora ponta e gestao ativa de demanda | D1: Caso-base eletrico: Cemig A4 Verde 360 kW; cominuicao fora ponta; pirolise 24h
B2: Indicadores consolidados do cenario base. Consumo = potencia x fator de utilizacao.
B5: Base Operacional
B6: Modalidade eletrica base | C6: =PREMISSAS!$C$47 -> Cemig A4 Verde 360 kW | D6: contrato
B7: Biomassa processada (ano base) | C7: =CÁLCULO!F4 -> 3940.8425 | D7: t/ano
B8: Dias de operacao/ano | C8: =CÁLCULO!F9 -> 164.20177 | D8: dias/ano
B9: Meses de calendario/ano | C9: =CÁLCULO!F10 -> 6.5680709 | D9: meses/ano
B10: Demanda contratada Cemig | C10: =PREMISSAS!$C$62 -> 360 | D10: kW
B11: Pico kW cominuicao completa | C11: 191.5 | D11: kW
B12: Pico kW pirolise | C12: 178.95 | D12: kW
B13: Pico tecnico sem gestao | C13: 370.45 | D13: kW
B15: kWh/t Fase 1 - pre-processamento | C15: 41.125 | D15: kWh/t
B16: kWh/t Fase 2 - reator | C16: 166.25 | D16: kWh/t
